Workbook

Sheet Funnel
A1: Level | B1: Id | C1: Role | D1: Lanes | E1: Target diff | F1: Band low | G1: Band high | H1: Random win rate | I1: Measured diff | J1: In band | K1: Ramps (columns x rows) | L1: Ramps | M1: Colours | N1: Stickmen | O1: Stickmen per colour | P1: Buses 4-seat | Q1: Buses 6-seat | R1: Buses 8-seat | S1: Buses 12-seat | T1: Buses total | U1: Blockers | V1: Tutorial / popup | W1: Road shape | X1: Ramp shape | Y1: Greedy 1x (s) | Z1: Greedy 2x (s) | AA1: Random wins | AB1: Random fails | AC1: Random unfinished | AD1: Ramp changes (did not fit the target zone)
A2: 1 | B2: f01 | C2: Tutorial | D2: 2 | E2: 1 | F2: 0.7 | G2: 1 | H2: =AA2/(AA2+AB2+AC2) | I2: =IF(H2>=1,1,INDEX(Summary!$B$48:$B$57,MATCH(H2,Summary!$A$48:$A$57,1))+(H2-INDEX(Summary!$A$48:$A$57,MATCH(H2,Summary!$A$48:$A$57,1)))*(INDEX(Summary!$B$48:$B$57,MATCH(H2,Summary!$A$48:$A$57,1)+1)-INDEX(Summary!$B$48:$B$57,MATCH(H2,Summary!$A$48:$A$57,1)))/(INDEX(Summary!$A$48:$A$57,MATCH(H2,Summary!$A$48:$A$57,1)+1)-INDEX(Summary!$A$48:$A$57,MATCH(H2,Summary!$A$48:$A$57,1)))) | J2: =AND(H2>=F2,H2<=G2) | K2: 4x4 | L2: 1 | M2: 2 | N2: 16 | O2: red 8, blue 8 | P2: 0 | Q2: 0 | R2: 2 | S2: 0 | T2: =SUM(P2:S2) | U2: - | V2: Tutorial: hand pointer, first sends | W2: short road, one gentle curve | X2: one diagonal ramp (built: straight, turned) | Y2: 13.5 | Z2: =Y2/2 | AA2: 200 | AB2: 0 | AC2: 0 | AD2: -
A3: 2 | B3: f02 | C3: Teach | D3: 2 | E3: 2 | F3: 0.7 | G3: 1 | H3: =AA3/(AA3+AB3+AC3) | I3: =IF(H3>=1,1,INDEX(Summary!$B$48:$B$57,MATCH(H3,Summary!$A$48:$A$57,1))+(H3-INDEX(Summary!$A$48:$A$57,MATCH(H3,Summary!$A$48:$A$57,1)))*(INDEX(Summary!$B$48:$B$57,MATCH(H3,Summary!$A$48:$A$57,1)+1)-INDEX(Summary!$B$48:$B$57,MATCH(H3,Summary!$A$48:$A$57,1)))/(INDEX(Summary!$A$48:$A$57,MATCH(H3,Summary!$A$48:$A$57,1)+1)-INDEX(Summary!$A$48:$A$57,MATCH(H3,Summary!$A$48:$A$57,1)))) | J3: =AND(H3>=F3,H3<=G3) | K3: 4x4, 4x4 | L3: 2 | M3: 3 | N3: 32 | O3: red 8, yellow 8, blue 16 | P3: 0 | Q3: 0 | R3: 4 | S3: 0 | T3: =SUM(P3:S3) | U3: - | V3: - | W3: S-curve, ramps on both sides | X3: square bleachers on both sides (built: straight, turned) | Y3: 17.9 | Z3: =Y3/2 | AA3: 200 | AB3: 0 | AC3: 0 | AD3: -
A4: 3 | B4: f03 | C4: Tutorial (bay re-send) | D4: 2 | E4: 2 | F4: 0.7 | G4: 1 | H4: =AA4/(AA4+AB4+AC4) | I4: =IF(H4>=1,1,INDEX(Summary!$B$48:$B$57,MATCH(H4,Summary!$A$48:$A$57,1))+(H4-INDEX(Summary!$A$48:$A$57,MATCH(H4,Summary!$A$48:$A$57,1)))*(INDEX(Summary!$B$48:$B$57,MATCH(H4,Summary!$A$48:$A$57,1)+1)-INDEX(Summary!$B$48:$B$57,MATCH(H4,Summary!$A$48:$A$57,1)))/(INDEX(Summary!$A$48:$A$57,MATCH(H4,Summary!$A$48:$A$57,1)+1)-INDEX(Summary!$A$48:$A$57,MATCH(H4,Summary!$A$48:$A$57,1)))) | J4: =AND(H4>=F4,H4<=G4) | K4: 5x4, 5x4 | L4: 2 | M4: 3 | N4: 40 | O4: red 8, yellow 16, blue 16 | P4: 0 | Q4: 0 | R4: 5 | S4: 0 | T4: =SUM(P4:S4) | U4: - | V4: Tutorial: hand pointer, parked bus re-send | W4: longer S-curve | X4: two diagonal ramps (built: straight, square to the road, straight, turned) | Y4: 38.7 | Z4: =Y4/2 | AA4: 200 | AB4: 0 | AC4: 0 | AD4: -
A5: 4 | B5: f04 | C5: Teach (bus sizes) | D5: 2 | E5: 3 | F5: 0.55 | G5: 0.75 | H5: =AA5/(AA5+AB5+AC5) | I5: =IF(H5>=1,1,INDEX(Summary!$B$48:$B$57,MATCH(H5,Summary!$A$48:$A$57,1))+(H5-INDEX(Summary!$A$48:$A$57,MATCH(H5,Summary!$A$48:$A$57,1)))*(INDEX(Summary!$B$48:$B$57,MATCH(H5,Summary!$A$48:$A$57,1)+1)-INDEX(Summary!$B$48:$B$57,MATCH(H5,Summary!$A$48:$A$57,1)))/(INDEX(Summary!$A$48:$A$57,MATCH(H5,Summary!$A$48:$A$57,1)+1)-INDEX(Summary!$A$48:$A$57,MATCH(H5,Summary!$A$48:$A$57,1)))) | J5: =AND(H5>=F5,H5<=G5) | K5: 4x7, 4x6 | L5: 2 | M5: 4 | N5: 52 | O5: red 12, yellow 16, green 12, blue 12 | P5: 5 | Q5: 0 | R5: 1 | S5: 2 | T5: =SUM(P5:S5) | U5: - | V5: - | W5: long almost straight road | X5: long narrow diagonal ramps (built: straight, turned) | Y5: 33.8 | Z5: =Y5/2 | AA5: 200 | AB5: 0 | AC5: 0 | AD5: -
A6: 5 | B6: f05 | C6: Fun | D6: 2 | E6: 2 | F6: 0.7 | G6: 1 | H6: =AA6/(AA6+AB6+AC6) | I6: =IF(H6>=1,1,INDEX(Summary!$B$48:$B$57,MATCH(H6,Summary!$A$48:$A$57,1))+(H6-INDEX(Summary!$A$48:$A$57,MATCH(H6,Summary!$A$48:$A$57,1)))*(INDEX(Summary!$B$48:$B$57,MATCH(H6,Summary!$A$48:$A$57,1)+1)-INDEX(Summary!$B$48:$B$57,MATCH(H6,Summary!$A$48:$A$57,1)))/(INDEX(Summary!$A$48:$A$57,MATCH(H6,Summary!$A$48:$A$57,1)+1)-INDEX(Summary!$A$48:$A$57,MATCH(H6,Summary!$A$48:$A$57,1)))) | J6: =AND(H6>=F6,H6<=G6) | K6: 4x6, 4x5, 4x5 | L6: 3 | M6: 4 | N6: 64 | O6: red 16, yellow 20, green 12, blue 16 | P6: 0 | Q6: 0 | R6: 5 | S6: 2 | T6: =SUM(P6:S6) | U6: - | V6: - | W6: first spiral | X6: bleachers before and after the spiral (built: straight, turned) | Y6: 33.9 | Z6: =Y6/2 | AA6: 200 | AB6: 0 | AC6: 0 | AD6: -
A7: 6 | B7: f06 | C7: Challenge | D7: 3 | E7: 5 | F7: 0.35 | G7: 0.5 | H7: =AA7/(AA7+AB7+AC7) | I7: =IF(H7>=1,1,INDEX(Summary!$B$48:$B$57,MATCH(H7,Summary!$A$48:$A$57,1))+(H7-INDEX(Summary!$A$48:$A$57,MATCH(H7,Summary!$A$48:$A$57,1)))*(INDEX(Summary!$B$48:$B$57,MATCH(H7,Summary!$A$48:$A$57,1)+1)-INDEX(Summary!$B$48:$B$57,MATCH(H7,Summary!$A$48:$A$57,1)))/(INDEX(Summary!$A$48:$A$57,MATCH(H7,Summary!$A$48:$A$57,1)+1)-INDEX(Summary!$A$48:$A$57,MATCH(H7,Summary!$A$48:$A$57,1)))) | J7: =AND(H7>=F7,H7<=G7) | K7: 6x4, 6x4, 6x4 | L7: 3 | M7: 4 | N7: 72 | O7: red 16, yellow 16, green 20, blue 20 | P7: 9 | Q7: 0 | R7: 3 | S7: 1 | T7: =SUM(P7:S7) | U7: - | V7: - | W7: zigzag | X7: wide shallow bleachers outside the corners (built: straight, turned) | Y7: 71.9 | Z7: =Y7/2 | AA7: 197 | AB7: 3 | AC7: 0 | AD7: -
A8: 7 | B8: f07 | C8: Teach + POPUP | D8: 3 | E8: 3 | F8: 0.55 | G8: 0.75 | H8: =AA8/(AA8+AB8+AC8) | I8: =IF(H8>=1,1,INDEX(Summary!$B$48:$B$57,MATCH(H8,Summary!$A$48:$A$57,1))+(H8-INDEX(Summary!$A$48:$A$57,MATCH(H8,Summary!$A$48:$A$57,1)))*(INDEX(Summary!$B$48:$B$57,MATCH(H8,Summary!$A$48:$A$57,1)+1)-INDEX(Summary!$B$48:$B$57,MATCH(H8,Summary!$A$48:$A$57,1)))/(INDEX(Summary!$A$48:$A$57,MATCH(H8,Summary!$A$48:$A$57,1)+1)-INDEX(Summary!$A$48:$A$57,MATCH(H8,Summary!$A$48:$A$57,1)))) | J8: =AND(H8>=F8,H8<=G8) | K8: 8x4, 8x4 | L8: 2 | M8: 4 | N8: 64 | O8: red 12, yellow 20, green 16, blue 16 | P8: 3 | Q8: 0 | R8: 2 | S8: 3 | T8: =SUM(P8:S8) | U8: 5 hidden buses | V8: Intro popup: Hidden Bus | W8: wide hairpin | X8: one ramp inside the hairpin, one outside (built: straight, turned) | Y8: 46.1 | Z8: =Y8/2 | AA8: 200 | AB8: 0 | AC8: 0 | AD8: -
A9: 8 | B9: f08 | C9: Practice | D9: 3 | E9: 5 | F9: 0.35 | G9: 0.5 | H9: =AA9/(AA9+AB9+AC9) | I9: =IF(H9>=1,1,INDEX(Summary!$B$48:$B$57,MATCH(H9,Summary!$A$48:$A$57,1))+(H9-INDEX(Summary!$A$48:$A$57,MATCH(H9,Summary!$A$48:$A$57,1)))*(INDEX(Summary!$B$48:$B$57,MATCH(H9,Summary!$A$48:$A$57,1)+1)-INDEX(Summary!$B$48:$B$57,MATCH(H9,Summary!$A$48:$A$57,1)))/(INDEX(Summary!$A$48:$A$57,MATCH(H9,Summary!$A$48:$A$57,1)+1)-INDEX(Summary!$A$48:$A$57,MATCH(H9,Summary!$A$48:$A$57,1)))) | J9: =AND(H9>=F9,H9<=G9) | K9: 7x4, 7x4, 7x4 | L9: 3 | M9: 5 | N9: 84 | O9: red 20, yellow 16, green 16, blue 20, purple 12 | P9: 12 | Q9: 0 | R9: 3 | S9: 1 | T9: =SUM(P9:S9) | U9: 2 hidden buses | V9: - | W9: S-curve + spiral | X9: curved arc ramps (built: straight, turned) | Y9: 63.9 | Z9: =Y9/2 | AA9: 184 | AB9: 16 | AC9: 0 | AD9: -
A10: 9 | B10: f09 | C10: Relax | D10: 2 | E10: 3 | F10: 0.55 | G10: 0.75 | H10: =AA10/(AA10+AB10+AC10) | I10: =IF(H10>=1,1,INDEX(Summary!$B$48:$B$57,MATCH(H10,Summary!$A$48:$A$57,1))+(H10-INDEX(Summary!$A$48:$A$57,MATCH(H10,Summary!$A$48:$A$57,1)))*(INDEX(Summary!$B$48:$B$57,MATCH(H10,Summary!$A$48:$A$57,1)+1)-INDEX(Summary!$B$48:$B$57,MATCH(H10,Summary!$A$48:$A$57,1)))/(INDEX(Summary!$A$48:$A$57,MATCH(H10,Summary!$A$48:$A$57,1)+1)-INDEX(Summary!$A$48:$A$57,MATCH(H10,Summary!$A$48:$A$57,1)))) | J10: =AND(H10>=F10,H10<=G10) | K10: 4x10, 4x9 | L10: 2 | M10: 4 | N10: 76 | O10: red 22, yellow 18, green 22, blue 14 | P10: 0 | Q10: 4 | R10: 5 | S10: 1 | T10: =SUM(P10:S10) | U10: - | V10: - | W10: long gentle curve | X10: long narrow diagonal ramps (built: straight, turned) | Y10: 65.3 | Z10: =Y10/2 | AA10: 200 | AB10: 0 | AC10: 0 | AD10: -
A11: 10 | B11: f10 | C11: Milestone | D11: 3 | E11: 6 | F11: 0.25 | G11: 0.4 | H11: =AA11/(AA11+AB11+AC11) | I11: =IF(H11>=1,1,INDEX(Summary!$B$48:$B$57,MATCH(H11,Summary!$A$48:$A$57,1))+(H11-INDEX(Summary!$A$48:$A$57,MATCH(H11,Summary!$A$48:$A$57,1)))*(INDEX(Summary!$B$48:$B$57,MATCH(H11,Summary!$A$48:$A$57,1)+1)-INDEX(Summary!$B$48:$B$57,MATCH(H11,Summary!$A$48:$A$57,1)))/(INDEX(Summary!$A$48:$A$57,MATCH(H11,Summary!$A$48:$A$57,1)+1)-INDEX(Summary!$A$48:$A$57,MATCH(H11,Summary!$A$48:$A$57,1)))) | J11: =AND(H11>=F11,H11<=G11) | K11: 8x5, 8x4, 8x4 | L11: 3 | M11: 5 | N11: 104 | O11: red 22, yellow 22, green 20, blue 22, purple 18 | P11: 2 | Q11: 4 | R11: 3 | S11: 4 | T11: =SUM(P11:S11) | U11: 3 hidden buses | V11: - | W11: double S | X11: bleachers in the S pockets (built: straight, turned) | Y11: 91.2 | Z11: =Y11/2 | AA11: 120 | AB11: 80 | AC11: 0 | AD11: -
A12: 11 | B12: f11 | C12: Relax | D12: 3 | E12: 3 | F12: 0.55 | G12: 0.75 | H12: =AA12/(AA12+AB12+AC12) | I12: =IF(H12>=1,1,INDEX(Summary!$B$48:$B$57,MATCH(H12,Summary!$A$48:$A$57,1))+(H12-INDEX(Summary!$A$48:$A$57,MATCH(H12,Summary!$A$48:$A$57,1)))*(INDEX(Summary!$B$48:$B$57,MATCH(H12,Summary!$A$48:$A$57,1)+1)-INDEX(Summary!$B$48:$B$57,MATCH(H12,Summary!$A$48:$A$57,1)))/(INDEX(Summary!$A$48:$A$57,MATCH(H12,Summary!$A$48:$A$57,1)+1)-INDEX(Summary!$A$48:$A$57,MATCH(H12,Summary!$A$48:$A$57,1)))) | J12: =AND(H12>=F12,H12<=G12) | K12: 6x7, 6x7 | L12: 2 | M12: 4 | N12: 84 | O12: red 20, yellow 24, green 24, blue 16 | P12: 0 | Q12: 4 | R12: 6 | S12: 1 | T12: =SUM(P12:S12) | U12: - | V12: - | W12: wide loop | X12: curved arc ramps inside the loop (built: straight, square to the road, straight, turned) | Y12: 75.6 | Z12: =Y12/2 | AA12: 145 | AB12: 55 | AC12: 0 | AD12: -
A13: 12 | B13: f12 | C13: Challenge | D13: 3 | E13: 6 | F13: 0.25 | G13: 0.4 | H13: =AA13/(AA13+AB13+AC13) | I13: =IF(H13>=1,1,INDEX(Summary!$B$48:$B$57,MATCH(H13,Summary!$A$48:$A$57,1))+(H13-INDEX(Summary!$A$48:$A$57,MATCH(H13,Summary!$A$48:$A$57,1)))*(INDEX(Summary!$B$48:$B$57,MATCH(H13,Summary!$A$48:$A$57,1)+1)-INDEX(Summary!$B$48:$B$57,MATCH(H13,Summary!$A$48:$A$57,1)))/(INDEX(Summary!$A$48:$A$57,MATCH(H13,Summary!$A$48:$A$57,1)+1)-INDEX(Summary!$A$48:$A$57,MATCH(H13,Summary!$A$48:$A$57,1)))) | J13: =AND(H13>=F13,H13<=G13) | K13: 7x4, 7x4, 7x4, 7x4 | L13: 4 | M13: 5 | N13: 112 | O13: red 26, yellow 22, green 26, blue 18, purple 20 | P13: 4 | Q13: 6 | R13: 3 | S13: 3 | T13: =SUM(P13:S13) | U13: 2 hidden buses | V13: - | W13: straight road with a slight wave | X13: four bleachers alternating sides (built: straight, turned) | Y13: 77.3 | Z13: =Y13/2 | AA13: 123 | AB13: 77 | AC13: 0 | AD13: -
... A41: 40 | B41: f40 | C41: Finale | D41: 5 | E41: 9 | F41: 0.08 | G41: 0.15 | H41: =AA41/(AA41+AB41+AC41) | I41: =IF(H41>=1,1,INDEX(Summary!$B$48:$B$57,MATCH(H41,Summary!$A$48:$A$57,1))+(H41-INDEX(Summary!$A$48:$A$57,MATCH(H41,Summary!$A$48:$A$57,1)))*(INDEX(Summary!$B$48:$B$57,MATCH(H41,Summary!$A$48:$A$57,1)+1)-INDEX(Summary!$B$48:$B$57,MATCH(H41,Summary!$A$48:$A$57,1)))/(INDEX(Summary!$A$48:$A$57,MATCH(H41,Summary!$A$48:$A$57,1)+1)-INDEX(Summary!$A$48:$A$57,MATCH(H41,Summary!$A$48:$A$57,1)))) | J41: =AND(H41>=F41,H41<=G41) | K41: 8x6, 8x6, 8x8, 8x6, 8x8, 4x12 | L41: 6 | M41: 8 | N41: 320 | O41: red 34, orange 40, yellow 46, green 40, cyan 44, blue 42, purple 44, pink 30 | P41: 18 | Q41: 10 | R41: 7 | S41: 11 | T41: =SUM(P41:S41) | U41: 3 hidden buses, 4 connected pairs, 4 connected triples, tunnel (purple, 8), tunnel (purple, 8), 2 lock boxes & keys | V41: - | W41: longest road, two spirals | X41: six ramps, two big ones (built: straight, turned) | Y41: 294.2 | Z41: =Y41/2 | AA41: 20 | AB41: 180 | AC41: 0 | AD41: ramp 3: shape perp did not fit, built as diag; ramp 6: 8x6 did not fit, built as 4x12
A42: Total | J42: =COUNTIF(J2:J41,TRUE)&" / 40" | N42: =SUM(N2:N41) | T42: =SUM(T2:T41) | Y42: =SUM(Y2:Y41) | Z42: =SUM(Z2:Z41) | AA42: =SUM(AA2:AA41) | AB42: =SUM(AB2:AB41) | AC42: =SUM(AC2:AC41)
A44: Target diff and band: the design table (random-bot win rate band per difficulty: 1-2 >= 70%, 3: 55-75%, 4: 45-60%, 5: 35-50%, 6: 25-40%, 7: 18-30%, 8: 12-22%, 9: 8-15%).
A45: Random bot: 200 games per level (seeds 1000-1199), a uniformly random legal send every 0.4 s whenever the road counter is below 5. Win rate = wins / games.
A46: Random fails: a returning bus found no free bay. Unfinished: no result after 1500 game seconds - the bot kept re-sending buses that could not fill, so the road never had room for the rest (a player who waits can always go on). Unfinished games count as not won.
A47: Measured diff: the win rate placed on the difficulty scale on the Summary sheet (straight-line between band centres).
A48: Greedy 1x: game seconds for the greedy bot (always sends the bus with the most matching stickmen at the fronts, waits when nothing matches). 2x = the same game at double speed.
A49: Levels 1-5 cannot be lost (no fail before level 6): each was played 1000 times by the random bot and 6 times by an adversarial bot without a loss. That puts level 4 above its band (55-75%).
A50: Lanes: queue lanes (2-5). Challenge, Milestone, Finale and Practice levels must land in their band; Relax, Fun and Teach levels may be easier.
A51: Out of band, closest version kept: f06 (98.5%, band 35-50%), f08 (92.0%, band 35-50%), f10 (60.0%, band 25-40%), f12 (61.5%, band 25-40%). Small 3-lane levels: stickman order, bus order / sizes and blocker placement alone cannot make a random player fail that often under the current rules.

Sheet Curve
A1: Level | B1: Target diff | C1: Measured diff | D1: Stickmen
A2: =Funnel!A2 | B2: =Funnel!E2 | C2: =Funnel!I2 | D2: =Funnel!N2
A3: =Funnel!A3 | B3: =Funnel!E3 | C3: =Funnel!I3 | D3: =Funnel!N3
A4: =Funnel!A4 | B4: =Funnel!E4 | C4: =Funnel!I4 | D4: =Funnel!N4
A5: =Funnel!A5 | B5: =Funnel!E5 | C5: =Funnel!I5 | D5: =Funnel!N5
A6: =Funnel!A6 | B6: =Funnel!E6 | C6: =Funnel!I6 | D6: =Funnel!N6
A7: =Funnel!A7 | B7: =Funnel!E7 | C7: =Funnel!I7 | D7: =Funnel!N7
A8: =Funnel!A8 | B8: =Funnel!E8 | C8: =Funnel!I8 | D8: =Funnel!N8
A9: =Funnel!A9 | B9: =Funnel!E9 | C9: =Funnel!I9 | D9: =Funnel!N9
A10: =Funnel!A10 | B10: =Funnel!E10 | C10: =Funnel!I10 | D10: =Funnel!N10
A11: =Funnel!A11 | B11: =Funnel!E11 | C11: =Funnel!I11 | D11: =Funnel!N11
A12: =Funnel!A12 | B12: =Funnel!E12 | C12: =Funnel!I12 | D12: =Funnel!N12
A13: =Funnel!A13 | B13: =Funnel!E13 | C13: =Funnel!I13 | D13: =Funnel!N13
... A41: =Funnel!A41 | B41: =Funnel!E41 | C41: =Funnel!I41 | D41: =Funnel!N41

Sheet Summary
A1: Match Express - 40-level funnel
A3: Playtime (greedy bot) | B3: Seconds | C3: Minutes | D3: Note
A4: Total, all 40 levels, at 1x | B4: =SUM(Funnel!Y2:Y41) | C4: =B4/60 | D4: Game time of the greedy bot (a player who never waits needlessly)
A5: Total, all 40 levels, at 2x | B5: =SUM(Funnel!Z2:Z41) | C5: =B5/60 | D5: Target: at least 35 minutes at 2x
A6: Meets the 35-minute target at 2x | B6: =C5>=35
A8: First session estimate (levels 1-12) | B8: Seconds | C8: Minutes | D8: Note
A9: Levels 1-12 at 1x | B9: =SUM(Funnel!Y2:Y13) | C9: =B9/60 | D9: Greedy play: the fastest clean run
A10: Levels 1-12 at 2x | B10: =SUM(Funnel!Z2:Z13) | C10: =B10/60
A11: Levels 1-12 at 1x, with menus and retries | B11: =B9*B12 | C11: =B11/60 | D11: Greedy time times the factor below
A12: Factor for a first-time player (assumption) | B12: 1.5 | D12: Assumption, edit to taste: popups, tutorials, thinking and the odd retry
A14: Blocker introductions | B14: Level | D14: How it is introduced
A15: Hidden Bus | B15: 7 | D15: Intro popup (first appearance only)
A16: Connected Buses (pairs) | B16: 13 | D16: Intro popup (first appearance only)
A17: Hidden Bus + Connected (first combination) | B17: 16 | D17: No popup
A18: Connected triple | B18: 17 | D18: Short non-blocking hint
A19: Colorful Tunnel | B19: 26 | D19: Intro popup (first appearance only)
A20: Lock & Key | B20: 32 | D20: Intro popup (first appearance only)
A21: All four blockers together | B21: 40 | D21: No popup (finale)
A23: Levels per role | B23: Levels
A24: Tutorial | B24: =COUNTIF(Funnel!C2:C41,"Tutorial*")
A25: Teach | B25: =COUNTIF(Funnel!C2:C41,"Teach*")
A26: Practice | B26: =COUNTIF(Funnel!C2:C41,"Practice*")
A27: Fun | B27: =COUNTIF(Funnel!C2:C41,"Fun*")
A28: Relax | B28: =COUNTIF(Funnel!C2:C41,"Relax*")
A29: Challenge | B29: =COUNTIF(Funnel!C2:C41,"Challenge*")
A30: Milestone | B30: =COUNTIF(Funnel!C2:C41,"Milestone*")
A31: Finale | B31: =COUNTIF(Funnel!C2:C41,"Finale*")
A32: Total | B32: =SUM(B24:B31)
A34: Levels in their difficulty band | B34: =COUNTIF(Funnel!J2:J41,TRUE) | D34: Random-bot win rate inside the target band
A36: Levels per queue size | B36: Levels | D36: Which
A37: 2 lanes | B37: =COUNTIF(Funnel!D2:D41,2) | D37: f01, f02, f03, f04, f05, f09, f22, f31
A38: 3 lanes | B38: =COUNTIF(Funnel!D2:D41,3) | D38: all others
A39: 4 lanes | B39: =COUNTIF(Funnel!D2:D41,4) | D39: f16, f20, f23, f35
A40: 5 lanes | B40: =COUNTIF(Funnel!D2:D41,5) | D40: f38, f40
A46: Difficulty scale (used by Funnel!Measured diff)
A47: Random win rate (band centre) | B47: Difficulty | D47: Note
A48: 0 | B48: 10 | D48: No wins
A49: 0.115 | B49: 9 | D49: Centre of the target band
A50: 0.17 | B50: 8 | D50: Centre of the target band
A51: 0.24 | B51: 7 | D51: Centre of the target band
...
