Workbook

Sheet Funnel
A1: Level | B1: Id | C1: Role | D1: Lanes | E1: Target diff | F1: Band low | G1: Band high | H1: Random win rate | I1: Measured diff | J1: In band | K1: Trays (columns x rows) | L1: Trays | M1: Colours | N1: Marbles | O1: Marbles per colour | P1: Boxes 4 | Q1: Boxes 6 | R1: Boxes 8 | S1: Boxes 12 | T1: Boxes total | U1: Blockers | V1: Tutorial / popup | W1: Slide shape | X1: Tray shape | Y1: Greedy 1x (s) | Z1: Greedy 2x (s) | AA1: Random wins | AB1: Random fails | AC1: Random unfinished | AD1: Tray changes (did not fit as asked)
A2: 1 | B2: f01 | C2: Tutorial | D2: 2 | E2: 1 | F2: 0.7 | G2: 1 | H2: =AA2/(AA2+AB2+AC2) -> 1 | I2: =IF(H2>=1,1,INDEX(Summary!$B$48:$B$57,MATCH(H2,Summary!$A$48:$A$57,1))+(H2-INDEX(Summary!$A$48:$A$57,MATCH(H2,Summary!$A$48:$A$57,1)))*(INDEX(Summary!$B$48:$B$57,MATCH(H2,Summary!$A$48:$A$57,1)+1)-INDEX(Summary!$B$48:$B$57,MATCH(H2,Summary!$A$48:$A$57,1)))/(INDEX(Summary!$A$48:$A$57,MATCH(H2,Summary!$A$48:$A$57,1)+1)-INDEX(Summary!$A$48:$A$57,MATCH(H2,Summary!$A$48:$A$57,1)))) -> 1 | J2: =AND(H2>=F2,H2<=G2) -> TRUE | K2: 4x4 | L2: 1 | M2: 2 | N2: 16 | O2: red 8, blue 8 | P2: 0 | Q2: 0 | R2: 2 | S2: 0 | T2: =SUM(P2:S2) -> 2 | U2: - | V2: Tutorial: hand pointer, first sends | W2: a short S-curve | X2: one tray (built: default (35 deg)) | Y2: 5.3 | Z2: =Y2/2 -> 2.65 | AA2: 200 | AB2: 0 | AC2: 0 | AD2: -
A3: 2 | B3: f02 | C3: Teach | D3: 2 | E3: 2 | F3: 0.7 | G3: 1 | H3: =AA3/(AA3+AB3+AC3) -> 1 | I3: =IF(H3>=1,1,INDEX(Summary!$B$48:$B$57,MATCH(H3,Summary!$A$48:$A$57,1))+(H3-INDEX(Summary!$A$48:$A$57,MATCH(H3,Summary!$A$48:$A$57,1)))*(INDEX(Summary!$B$48:$B$57,MATCH(H3,Summary!$A$48:$A$57,1)+1)-INDEX(Summary!$B$48:$B$57,MATCH(H3,Summary!$A$48:$A$57,1)))/(INDEX(Summary!$A$48:$A$57,MATCH(H3,Summary!$A$48:$A$57,1)+1)-INDEX(Summary!$A$48:$A$57,MATCH(H3,Summary!$A$48:$A$57,1)))) -> 1 | J3: =AND(H3>=F3,H3<=G3) -> TRUE | K3: 3x4, 3x4 | L3: 2 | M3: 3 | N3: 24 | O3: red 8, yellow 8, blue 8 | P3: 0 | Q3: 0 | R3: 3 | S3: 0 | T3: =SUM(P3:S3) -> 3 | U3: - | V3: - | W3: the spiral early | X3: two small trays (built: default (35 deg)) | Y3: 7.4 | Z3: =Y3/2 -> 3.7 | AA3: 200 | AB3: 0 | AC3: 0 | AD3: -
A4: 3 | B4: f03 | C4: Tutorial (box waits) | D4: 2 | E4: 2 | F4: 0.7 | G4: 1 | H4: =AA4/(AA4+AB4+AC4) -> 1 | I4: =IF(H4>=1,1,INDEX(Summary!$B$48:$B$57,MATCH(H4,Summary!$A$48:$A$57,1))+(H4-INDEX(Summary!$A$48:$A$57,MATCH(H4,Summary!$A$48:$A$57,1)))*(INDEX(Summary!$B$48:$B$57,MATCH(H4,Summary!$A$48:$A$57,1)+1)-INDEX(Summary!$B$48:$B$57,MATCH(H4,Summary!$A$48:$A$57,1)))/(INDEX(Summary!$A$48:$A$57,MATCH(H4,Summary!$A$48:$A$57,1)+1)-INDEX(Summary!$A$48:$A$57,MATCH(H4,Summary!$A$48:$A$57,1)))) -> 1 | J4: =AND(H4>=F4,H4<=G4) -> TRUE | K4: 4x4, 4x4 | L4: 2 | M4: 3 | N4: 32 | O4: red 8, yellow 16, blue 8 | P4: 0 | Q4: 0 | R4: 4 | S4: 0 | T4: =SUM(P4:S4) -> 4 | U4: - | V4: Tutorial: a box waits in its slot | W4: winding | X4: two trays, one each side (built: default (35 deg), turned) | Y4: 7.5 | Z4: =Y4/2 -> 3.75 | AA4: 200 | AB4: 0 | AC4: 0 | AD4: tray 2: shape tilt did not fit, built as diag
A5: 4 | B5: f04 | C5: Teach (box sizes) | D5: 2 | E5: 3 | F5: 0.55 | G5: 0.75 | H5: =AA5/(AA5+AB5+AC5) -> 1 | I5: =IF(H5>=1,1,INDEX(Summary!$B$48:$B$57,MATCH(H5,Summary!$A$48:$A$57,1))+(H5-INDEX(Summary!$A$48:$A$57,MATCH(H5,Summary!$A$48:$A$57,1)))*(INDEX(Summary!$B$48:$B$57,MATCH(H5,Summary!$A$48:$A$57,1)+1)-INDEX(Summary!$B$48:$B$57,MATCH(H5,Summary!$A$48:$A$57,1)))/(INDEX(Summary!$A$48:$A$57,MATCH(H5,Summary!$A$48:$A$57,1)+1)-INDEX(Summary!$A$48:$A$57,MATCH(H5,Summary!$A$48:$A$57,1)))) -> 1 | J5: =AND(H5>=F5,H5<=G5) -> FALSE | K5: 3x6, 3x6 | L5: 2 | M5: 4 | N5: 36 | O5: red 8, yellow 8, green 8, blue 12 | P5: 2 | Q5: 0 | R5: 2 | S5: 1 | T5: =SUM(P5:S5) -> 5 | U5: - | V5: - | W5: S-curve | X5: two deep trays (built: default (35 deg), tilted 55 deg) | Y5: 8.6 | Z5: =Y5/2 -> 4.3 | AA5: 200 | AB5: 0 | AC5: 0 | AD5: tray 2: shape tilt did not fit, built as tilt 55
A6: 5 | B6: f05 | C6: Fun | D6: 2 | E6: 2 | F6: 0.7 | G6: 1 | H6: =AA6/(AA6+AB6+AC6) -> 1 | I6: =IF(H6>=1,1,INDEX(Summary!$B$48:$B$57,MATCH(H6,Summary!$A$48:$A$57,1))+(H6-INDEX(Summary!$A$48:$A$57,MATCH(H6,Summary!$A$48:$A$57,1)))*(INDEX(Summary!$B$48:$B$57,MATCH(H6,Summary!$A$48:$A$57,1)+1)-INDEX(Summary!$B$48:$B$57,MATCH(H6,Summary!$A$48:$A$57,1)))/(INDEX(Summary!$A$48:$A$57,MATCH(H6,Summary!$A$48:$A$57,1)+1)-INDEX(Summary!$A$48:$A$57,MATCH(H6,Summary!$A$48:$A$57,1)))) -> 1 | J6: =AND(H6>=F6,H6<=G6) -> TRUE | K6: 3x6, 3x6, 3x6 | L6: 3 | M6: 4 | N6: 52 | O6: red 12, yellow 16, green 12, blue 12 | P6: 0 | Q6: 0 | R6: 2 | S6: 3 | T6: =SUM(P6:S6) -> 5 | U6: - | V6: - | W6: the first big spiral | X6: three trays around the spiral (built: default (35 deg), turned) | Y6: 9.5 | Z6: =Y6/2 -> 4.75 | AA6: 200 | AB6: 0 | AC6: 0 | AD6: tray 3: shape tilt did not fit, built as diag
A7: 6 | B7: f06 | C7: Challenge | D7: 3 | E7: 5 | F7: 0.35 | G7: 0.5 | H7: =AA7/(AA7+AB7+AC7) -> 0.36 | I7: =IF(H7>=1,1,INDEX(Summary!$B$48:$B$57,MATCH(H7,Summary!$A$48:$A$57,1))+(H7-INDEX(Summary!$A$48:$A$57,MATCH(H7,Summary!$A$48:$A$57,1)))*(INDEX(Summary!$B$48:$B$57,MATCH(H7,Summary!$A$48:$A$57,1)+1)-INDEX(Summary!$B$48:$B$57,MATCH(H7,Summary!$A$48:$A$57,1)))/(INDEX(Summary!$A$48:$A$57,MATCH(H7,Summary!$A$48:$A$57,1)+1)-INDEX(Summary!$A$48:$A$57,MATCH(H7,Summary!$A$48:$A$57,1)))) -> 5.65 | J7: =AND(H7>=F7,H7<=G7) -> TRUE | K7: 3x5, 3x5, 3x5, 3x5 | L7: 4 | M7: 5 | N7: 60 | O7: red 12, yellow 10, green 12, blue 16, purple 10 | P7: 4 | Q7: 4 | R7: 1 | S7: 1 | T7: =SUM(P7:S7) -> 10 | U7: - | V7: - | W7: hairpin | X7: four trays, two each side (built: default (35 deg), turned) | Y7: 27.2 | Z7: =Y7/2 -> 13.6 | AA7: 72 | AB7: 128 | AC7: 0 | AD7: tray 2: shape tilt did not fit, built as diag; tray 3: shape tilt did not fit, built as diag; tray 4: shape tilt did not fit, built as diag
A8: 7 | B8: f07 | C8: Teach + POPUP | D8: 3 | E8: 3 | F8: 0.55 | G8: 0.75 | H8: =AA8/(AA8+AB8+AC8) -> 1 | I8: =IF(H8>=1,1,INDEX(Summary!$B$48:$B$57,MATCH(H8,Summary!$A$48:$A$57,1))+(H8-INDEX(Summary!$A$48:$A$57,MATCH(H8,Summary!$A$48:$A$57,1)))*(INDEX(Summary!$B$48:$B$57,MATCH(H8,Summary!$A$48:$A$57,1)+1)-INDEX(Summary!$B$48:$B$57,MATCH(H8,Summary!$A$48:$A$57,1)))/(INDEX(Summary!$A$48:$A$57,MATCH(H8,Summary!$A$48:$A$57,1)+1)-INDEX(Summary!$A$48:$A$57,MATCH(H8,Summary!$A$48:$A$57,1)))) -> 1 | J8: =AND(H8>=F8,H8<=G8) -> FALSE | K8: 3x6, 3x6, 3x6 | L8: 3 | M8: 4 | N8: 52 | O8: red 12, yellow 12, green 16, blue 12 | P8: 6 | Q8: 0 | R8: 2 | S8: 1 | T8: =SUM(P8:S8) -> 9 | U8: 5 hidden boxes | V8: Intro popup: Hidden Box | W8: the spiral early | X8: three trays (built: default (35 deg), tilted 55 deg, turned) | Y8: 14.6 | Z8: =Y8/2 -> 7.3 | AA8: 200 | AB8: 0 | AC8: 0 | AD8: tray 2: shape tilt did not fit, built as tilt 55; tray 3: shape tilt did not fit, built as diag
A9: 8 | B9: f08 | C9: Practice | D9: 3 | E9: 5 | F9: 0.35 | G9: 0.5 | H9: =AA9/(AA9+AB9+AC9) -> 0.49 | I9: =IF(H9>=1,1,INDEX(Summary!$B$48:$B$57,MATCH(H9,Summary!$A$48:$A$57,1))+(H9-INDEX(Summary!$A$48:$A$57,MATCH(H9,Summary!$A$48:$A$57,1)))*(INDEX(Summary!$B$48:$B$57,MATCH(H9,Summary!$A$48:$A$57,1)+1)-INDEX(Summary!$B$48:$B$57,MATCH(H9,Summary!$A$48:$A$57,1)))/(INDEX(Summary!$A$48:$A$57,MATCH(H9,Summary!$A$48:$A$57,1)+1)-INDEX(Summary!$A$48:$A$57,MATCH(H9,Summary!$A$48:$A$57,1)))) -> 4.35 | J9: =AND(H9>=F9,H9<=G9) -> TRUE | K9: 3x5, 3x5, 3x5, 3x5 | L9: 4 | M9: 5 | N9: 60 | O9: red 16, yellow 10, green 14, blue 10, purple 10 | P9: 4 | Q9: 4 | R9: 1 | S9: 1 | T9: =SUM(P9:S9) -> 10 | U9: 2 hidden boxes | V9: - | W9: zig-zag | X9: four trays at the turns (built: default (35 deg), tilted 55 deg, turned) | Y9: 23.8 | Z9: =Y9/2 -> 11.9 | AA9: 98 | AB9: 102 | AC9: 0 | AD9: tray 3: shape tilt did not fit, built as tilt 55; tray 4: shape tilt did not fit, built as diag
A10: 9 | B10: f09 | C10: Relax | D10: 2 | E10: 3 | F10: 0.55 | G10: 0.75 | H10: =AA10/(AA10+AB10+AC10) -> 1 | I10: =IF(H10>=1,1,INDEX(Summary!$B$48:$B$57,MATCH(H10,Summary!$A$48:$A$57,1))+(H10-INDEX(Summary!$A$48:$A$57,MATCH(H10,Summary!$A$48:$A$57,1)))*(INDEX(Summary!$B$48:$B$57,MATCH(H10,Summary!$A$48:$A$57,1)+1)-INDEX(Summary!$B$48:$B$57,MATCH(H10,Summary!$A$48:$A$57,1)))/(INDEX(Summary!$A$48:$A$57,MATCH(H10,Summary!$A$48:$A$57,1)+1)-INDEX(Summary!$A$48:$A$57,MATCH(H10,Summary!$A$48:$A$57,1)))) -> 1 | J10: =AND(H10>=F10,H10<=G10) -> FALSE | K10: 3x6, 3x6, 3x6 | L10: 3 | M10: 4 | N10: 54 | O10: red 14, yellow 12, green 14, blue 14 | P10: 0 | Q10: 3 | R10: 3 | S10: 1 | T10: =SUM(P10:S10) -> 7 | U10: - | V10: - | W10: winding | X10: three trays (built: default (35 deg), turned) | Y10: 12.7 | Z10: =Y10/2 -> 6.35 | AA10: 200 | AB10: 0 | AC10: 0 | AD10: tray 3: shape tilt did not fit, built as diag
A11: 10 | B11: f10 | C11: Milestone | D11: 3 | E11: 6 | F11: 0.25 | G11: 0.4 | H11: =AA11/(AA11+AB11+AC11) -> 0.38 | I11: =IF(H11>=1,1,INDEX(Summary!$B$48:$B$57,MATCH(H11,Summary!$A$48:$A$57,1))+(H11-INDEX(Summary!$A$48:$A$57,MATCH(H11,Summary!$A$48:$A$57,1)))*(INDEX(Summary!$B$48:$B$57,MATCH(H11,Summary!$A$48:$A$57,1)+1)-INDEX(Summary!$B$48:$B$57,MATCH(H11,Summary!$A$48:$A$57,1)))/(INDEX(Summary!$A$48:$A$57,MATCH(H11,Summary!$A$48:$A$57,1)+1)-INDEX(Summary!$A$48:$A$57,MATCH(H11,Summary!$A$48:$A$57,1)))) -> 5.45 | J11: =AND(H11>=F11,H11<=G11) -> TRUE | K11: 3x6, 3x6, 3x6, 3x6 | L11: 4 | M11: 6 | N11: 72 | O11: red 12, orange 14, yellow 10, green 12, blue 14, purple 10 | P11: 7 | Q11: 4 | R11: 1 | S11: 1 | T11: =SUM(P11:S11) -> 13 | U11: 3 hidden boxes | V11: - | W11: a meander with a spiral | X11: four trays (built: default (35 deg), turned) | Y11: 31.9 | Z11: =Y11/2 -> 15.95 | AA11: 76 | AB11: 124 | AC11: 0 | AD11: tray 1: shape tilt did not fit, built as diag; tray 2: shape tilt did not fit, built as diag; tray 4: shape tilt did not fit, built as diag
A12: 11 | B12: f11 | C12: Relax | D12: 3 | E12: 3 | F12: 0.55 | G12: 0.75 | H12: =AA12/(AA12+AB12+AC12) -> 1 | I12: =IF(H12>=1,1,INDEX(Summary!$B$48:$B$57,MATCH(H12,Summary!$A$48:$A$57,1))+(H12-INDEX(Summary!$A$48:$A$57,MATCH(H12,Summary!$A$48:$A$57,1)))*(INDEX(Summary!$B$48:$B$57,MATCH(H12,Summary!$A$48:$A$57,1)+1)-INDEX(Summary!$B$48:$B$57,MATCH(H12,Summary!$A$48:$A$57,1)))/(INDEX(Summary!$A$48:$A$57,MATCH(H12,Summary!$A$48:$A$57,1)+1)-INDEX(Summary!$A$48:$A$57,MATCH(H12,Summary!$A$48:$A$57,1)))) -> 1 | J12: =AND(H12>=F12,H12<=G12) -> FALSE | K12: 3x6, 3x6, 3x6 | L12: 3 | M12: 4 | N12: 54 | O12: red 14, yellow 12, green 14, blue 14 | P12: 0 | Q12: 3 | R12: 3 | S12: 1 | T12: =SUM(P12:S12) -> 7 | U12: - | V12: - | W12: spiral | X12: three trays square to the slide (built: turned) | Y12: 13.1 | Z12: =Y12/2 -> 6.55 | AA12: 200 | AB12: 0 | AC12: 0 | AD12: -
A13: 12 | B13: f12 | C13: Challenge | D13: 3 | E13: 6 | F13: 0.25 | G13: 0.4 | H13: =AA13/(AA13+AB13+AC13) -> 0.335 | I13: =IF(H13>=1,1,INDEX(Summary!$B$48:$B$57,MATCH(H13,Summary!$A$48:$A$57,1))+(H13-INDEX(Summary!$A$48:$A$57,MATCH(H13,Summary!$A$48:$A$57,1)))*(INDEX(Summary!$B$48:$B$57,MATCH(H13,Summary!$A$48:$A$57,1)+1)-INDEX(Summary!$B$48:$B$57,MATCH(H13,Summary!$A$48:$A$57,1)))/(INDEX(Summary!$A$48:$A$57,MATCH(H13,Summary!$A$48:$A$57,1)+1)-INDEX(Summary!$A$48:$A$57,MATCH(H13,Summary!$A$48:$A$57,1)))) -> 5.9 | J13: =AND(H13>=F13,H13<=G13) -> TRUE | K13: 3x7, 3x7, 3x7, 3x7 | L13: 4 | M13: 6 | N13: 84 | O13: red 12, orange 16, yellow 10, green 16, blue 18, purple 12 | P13: 2 | Q13: 2 | R13: 2 | S13: 4 | T13: =SUM(P13:S13) -> 10 | U13: 2 hidden boxes | V13: - | W13: the spiral early | X13: four deeper trays (built: default (35 deg), turned) | Y13: 29.9 | Z13: =Y13/2 -> 14.95 | AA13: 67 | AB13: 133 | AC13: 0 | AD13: tray 3: shape tilt did not fit, built as diag; tray 4: shape tilt did not fit, built as diag
... A41: 40 | B41: f40 | C41: Finale | D41: 5 | E41: 9 | F41: 0.08 | G41: 0.15 | H41: =AA41/(AA41+AB41+AC41) -> 0.09 | I41: =IF(H41>=1,1,INDEX(Summary!$B$48:$B$57,MATCH(H41,Summary!$A$48:$A$57,1))+(H41-INDEX(Summary!$A$48:$A$57,MATCH(H41,Summary!$A$48:$A$57,1)))*(INDEX(Summary!$B$48:$B$57,MATCH(H41,Summary!$A$48:$A$57,1)+1)-INDEX(Summary!$B$48:$B$57,MATCH(H41,Summary!$A$48:$A$57,1)))/(INDEX(Summary!$A$48:$A$57,MATCH(H41,Summary!$A$48:$A$57,1)+1)-INDEX(Summary!$A$48:$A$57,MATCH(H41,Summary!$A$48:$A$57,1)))) -> 9.2173913 | J41: =AND(H41>=F41,H41<=G41) -> TRUE | K41: 3x8, 3x8, 3x8, 3x8 | L41: 4 | M41: 8 | N41: 96 | O41: red 12, orange 12, yellow 14, green 8, cyan 14, blue 10, purple 14, pink 12 | P41: 10 | Q41: 6 | R41: 1 | S41: 1 | T41: =SUM(P41:S41) -> 18 | U41: 3 hidden boxes, 3 connected pairs, 3 connected triples, dispenser (blue, 8), dispenser (yellow, 8), lock crate & key, count crate (3) | V41: - | W41: the spiral early | X41: four deep trays, every blocker (built: default (35 deg), tilted 55 deg, turned) | Y41: 25.3 | Z41: =Y41/2 -> 12.65 | AA41: 18 | AB41: 182 | AC41: 0 | AD41: tray 2: shape tilt did not fit, built as tilt 55; tray 3: shape tilt did not fit, built as diag; tray 4: shape tilt did not fit, built as diag
A42: Total | J42: =COUNTIF(J2:J41,TRUE())&" / 40" -> 22 / 40 | N42: =SUM(N2:N41) -> 2868 | T42: =SUM(T2:T41) -> 423 | Y42: =SUM(Y2:Y41) -> 868.9 | Z42: =SUM(Z2:Z41) -> 434.45 | AA42: =SUM(AA2:AA41) -> 5196 | AB42: =SUM(AB2:AB41) -> 2804 | AC42: =SUM(AC2:AC41) -> 0
A44: Target diff and band: the design table (random-bot win rate band per difficulty: 1-2 >= 70%, 3: 55-75%, 4: 45-60%, 5: 35-50%, 6: 25-40%, 7: 18-30%, 8: 12-22%, 9: 8-15%).
A45: Random bot: 200 games per level (seeds 1000-1199), a uniformly random legal send (a front box to a free slot) every 0.4 s of game time. Win rate = wins / games.
A46: Random fails: Out of Space - all 5 slots hold boxes, nothing is moving and no tray front can go to any of them. Unfinished: no result after 1500 game seconds. Unfinished games count as not won.
A47: Measured diff: the win rate placed on the difficulty scale on the Summary sheet (straight-line between band centres).
A48: Greedy 1x: game seconds for the greedy bot (sends the box that gets the most marbles at once, waits while marbles are moving when nothing gains). 2x = the same game at double speed.
A49: Levels 1-5 cannot be lost (no fail before level 6): each was played 1000 times by the random bot and 6 times by an adversarial bot without a loss. That puts levels 3 and 4 above their bands.
A50: Lanes: box lanes (2-5). Challenge, Milestone, Finale and Practice levels must land in their band; Relax, Fun and Teach levels may be easier.
A51: Out of band, closest version kept: none.

Sheet Curve
A1: Level | B1: Target diff | C1: Measured diff | D1: Marbles
A2: =Funnel!A2 -> 1 | B2: =Funnel!E2 -> 1 | C2: =Funnel!I2 -> 1 | D2: =Funnel!N2 -> 16
A3: =Funnel!A3 -> 2 | B3: =Funnel!E3 -> 2 | C3: =Funnel!I3 -> 1 | D3: =Funnel!N3 -> 24
A4: =Funnel!A4 -> 3 | B4: =Funnel!E4 -> 2 | C4: =Funnel!I4 -> 1 | D4: =Funnel!N4 -> 32
A5: =Funnel!A5 -> 4 | B5: =Funnel!E5 -> 3 | C5: =Funnel!I5 -> 1 | D5: =Funnel!N5 -> 36
A6: =Funnel!A6 -> 5 | B6: =Funnel!E6 -> 2 | C6: =Funnel!I6 -> 1 | D6: =Funnel!N6 -> 52
A7: =Funnel!A7 -> 6 | B7: =Funnel!E7 -> 5 | C7: =Funnel!I7 -> 5.65 | D7: =Funnel!N7 -> 60
A8: =Funnel!A8 -> 7 | B8: =Funnel!E8 -> 3 | C8: =Funnel!I8 -> 1 | D8: =Funnel!N8 -> 52
A9: =Funnel!A9 -> 8 | B9: =Funnel!E9 -> 5 | C9: =Funnel!I9 -> 4.35 | D9: =Funnel!N9 -> 60
A10: =Funnel!A10 -> 9 | B10: =Funnel!E10 -> 3 | C10: =Funnel!I10 -> 1 | D10: =Funnel!N10 -> 54
A11: =Funnel!A11 -> 10 | B11: =Funnel!E11 -> 6 | C11: =Funnel!I11 -> 5.45 | D11: =Funnel!N11 -> 72
A12: =Funnel!A12 -> 11 | B12: =Funnel!E12 -> 3 | C12: =Funnel!I12 -> 1 | D12: =Funnel!N12 -> 54
A13: =Funnel!A13 -> 12 | B13: =Funnel!E13 -> 6 | C13: =Funnel!I13 -> 5.9 | D13: =Funnel!N13 -> 84
... A41: =Funnel!A41 -> 40 | B41: =Funnel!E41 -> 9 | C41: =Funnel!I41 -> 9.2173913 | D41: =Funnel!N41 -> 96

Sheet Summary
A1: Marble Run - 40-level funnel
A3: Playtime (greedy bot) | B3: Seconds | C3: Minutes | D3: Note
A4: Total, all 40 levels, at 1x | B4: =SUM(Funnel!Y2:Y41) -> 868.9 | C4: =B4/60 -> 14.481667 | D4: Game time of the greedy bot (a player who never waits needlessly)
A5: Total, all 40 levels, at 2x | B5: =SUM(Funnel!Z2:Z41) -> 434.45 | C5: =B5/60 -> 7.2408333 | D5: Target: at least 35 minutes at 2x
A6: Meets the 35-minute target at 2x | B6: =C5>=35 -> FALSE
A8: First session estimate (levels 1-12) | B8: Seconds | C8: Minutes | D8: Note
A9: Levels 1-12 at 1x | B9: =SUM(Funnel!Y2:Y13) -> 191.5 | C9: =B9/60 -> 3.1916667 | D9: Greedy play: the fastest clean run
A10: Levels 1-12 at 2x | B10: =SUM(Funnel!Z2:Z13) -> 95.75 | C10: =B10/60 -> 1.5958333
A11: Levels 1-12 at 1x, with menus and retries | B11: =B9*B12 -> 287.25 | C11: =B11/60 -> 4.7875 | D11: Greedy time times the factor below
A12: Factor for a first-time player (assumption) | B12: 1.5 | D12: Assumption, edit to taste: popups, tutorials, thinking and the odd retry
A14: Blocker introductions | B14: Level | D14: How it is introduced
A15: Hidden Box | B15: 7 | D15: Intro popup (first appearance only)
A16: Connected Boxes (pairs) | B16: 13 | D16: Intro popup (first appearance only)
A17: Connected triples | B17: 17 | D17: Short non-blocking hint
A18: Hidden Box + Connected (first combination) | B18: 21 | D18: No popup
A19: Hidden Marbles | B19: 22 | D19: Intro popup (first appearance only)
A20: Marble Dispenser | B20: 26 | D20: Intro popup (first appearance only)
A21: Lock & Key | B21: 32 | D21: Intro popup (first appearance only)
A22: Every blocker together | B22: 40 | D22: No popup (finale)
A24: Levels per role | B24: Levels
A25: Tutorial | B25: =COUNTIF(Funnel!C2:C41,"Tutorial*") -> 2
A26: Teach | B26: =COUNTIF(Funnel!C2:C41,"Teach*") -> 8
A27: Practice | B27: =COUNTIF(Funnel!C2:C41,"Practice*") -> 6
A28: Fun | B28: =COUNTIF(Funnel!C2:C41,"Fun*") -> 5
A29: Relax | B29: =COUNTIF(Funnel!C2:C41,"Relax*") -> 7
A30: Challenge | B30: =COUNTIF(Funnel!C2:C41,"Challenge*") -> 8
A31: Milestone | B31: =COUNTIF(Funnel!C2:C41,"Milestone*") -> 3
A32: Finale | B32: =COUNTIF(Funnel!C2:C41,"Finale*") -> 1
A33: Total | B33: =SUM(B25:B32) -> 40
A35: Levels in their difficulty band | B35: =COUNTIF(Funnel!J2:J41,TRUE()) -> 22 | D35: Random-bot win rate inside the target band
A37: Levels per box-lane count | B37: Levels | D37: Which
A38: 2 lanes | B38: =COUNTIF(Funnel!D2:D41,2) -> 8 | D38: f01, f02, f03, f04, f05, f09, f22, f31
A39: 3 lanes | B39: =COUNTIF(Funnel!D2:D41,3) -> 26 | D39: all others
A40: 4 lanes | B40: =COUNTIF(Funnel!D2:D41,4) -> 4 | D40: f16, f20, f23, f35
A41: 5 lanes | B41: =COUNTIF(Funnel!D2:D41,5) -> 2 | D41: f38, f40
A46: Difficulty scale (used by Funnel!Measured diff)
A47: Random win rate (band centre) | B47: Difficulty | D47: Note
A48: 0 | B48: 10 | D48: No wins
A49: 0.115 | B49: 9 | D49: Centre of the target band
A50: 0.17 | B50: 8 | D50: Centre of the target band
...
